/var/spool/slurmd/job2241708/slurm_script: line 13: conda: command not found
CUDA Available
Traceback (most recent call last):
  File "/home/vk9342/.conda/envs/usrp/lib/python3.11/site-packages/sqlalchemy/engine/base.py", line 1967, in _exec_single_context
    self.dialect.do_execute(
  File "/home/vk9342/.conda/envs/usrp/lib/python3.11/site-packages/sqlalchemy/engine/default.py", line 941, in do_execute
    cursor.execute(statement, parameters)
sqlite3.IntegrityError: UNIQUE constraint failed: studies.study_name

The above exception was the direct cause of the following exception:

Traceback (most recent call last):
  File "/home/vk9342/.conda/envs/usrp/lib/python3.11/site-packages/optuna/storages/_rdb/storage.py", line 264, in create_new_study
    with _create_scoped_session(self.scoped_session) as session:
  File "/home/vk9342/.conda/envs/usrp/lib/python3.11/contextlib.py", line 144, in __exit__
    next(self.gen)
  File "/home/vk9342/.conda/envs/usrp/lib/python3.11/site-packages/optuna/storages/_rdb/storage.py", line 73, in _create_scoped_session
    session.commit()
  File "/home/vk9342/.conda/envs/usrp/lib/python3.11/site-packages/sqlalchemy/orm/session.py", line 2028, in commit
    trans.commit(_to_root=True)
  File "<string>", line 2, in commit
  File "/home/vk9342/.conda/envs/usrp/lib/python3.11/site-packages/sqlalchemy/orm/state_changes.py", line 139, in _go
    ret_value = fn(self, *arg, **kw)
                ^^^^^^^^^^^^^^^^^^^^
  File "/home/vk9342/.conda/envs/usrp/lib/python3.11/site-packages/sqlalchemy/orm/session.py", line 1313, in commit
    self._prepare_impl()
  File "<string>", line 2, in _prepare_impl
  File "/home/vk9342/.conda/envs/usrp/lib/python3.11/site-packages/sqlalchemy/orm/state_changes.py", line 139, in _go
    ret_value = fn(self, *arg, **kw)
                ^^^^^^^^^^^^^^^^^^^^
  File "/home/vk9342/.conda/envs/usrp/lib/python3.11/site-packages/sqlalchemy/orm/session.py", line 1288, in _prepare_impl
    self.session.flush()
  File "/home/vk9342/.conda/envs/usrp/lib/python3.11/site-packages/sqlalchemy/orm/session.py", line 4352, in flush
    self._flush(objects)
  File "/home/vk9342/.conda/envs/usrp/lib/python3.11/site-packages/sqlalchemy/orm/session.py", line 4487, in _flush
    with util.safe_reraise():
  File "/home/vk9342/.conda/envs/usrp/lib/python3.11/site-packages/sqlalchemy/util/langhelpers.py", line 146, in __exit__
    raise exc_value.with_traceback(exc_tb)
  File "/home/vk9342/.conda/envs/usrp/lib/python3.11/site-packages/sqlalchemy/orm/session.py", line 4448, in _flush
    flush_context.execute()
  File "/home/vk9342/.conda/envs/usrp/lib/python3.11/site-packages/sqlalchemy/orm/unitofwork.py", line 466, in execute
    rec.execute(self)
  File "/home/vk9342/.conda/envs/usrp/lib/python3.11/site-packages/sqlalchemy/orm/unitofwork.py", line 642, in execute
    util.preloaded.orm_persistence.save_obj(
  File "/home/vk9342/.conda/envs/usrp/lib/python3.11/site-packages/sqlalchemy/orm/persistence.py", line 93, in save_obj
    _emit_insert_statements(
  File "/home/vk9342/.conda/envs/usrp/lib/python3.11/site-packages/sqlalchemy/orm/persistence.py", line 1233, in _emit_insert_statements
    result = connection.execute(
             ^^^^^^^^^^^^^^^^^^^
  File "/home/vk9342/.conda/envs/usrp/lib/python3.11/site-packages/sqlalchemy/engine/base.py", line 1418, in execute
    return meth(
           ^^^^^
  File "/home/vk9342/.conda/envs/usrp/lib/python3.11/site-packages/sqlalchemy/sql/elements.py", line 515, in _execute_on_connection
    return connection._execute_clauseelement(
           ^^^^^^^^^^^^^^^^^^^^^^^^^^^^^^^^^^
  File "/home/vk9342/.conda/envs/usrp/lib/python3.11/site-packages/sqlalchemy/engine/base.py", line 1640, in _execute_clauseelement
    ret = self._execute_context(
          ^^^^^^^^^^^^^^^^^^^^^^
  File "/home/vk9342/.conda/envs/usrp/lib/python3.11/site-packages/sqlalchemy/engine/base.py", line 1846, in _execute_context
    return self._exec_single_context(
           ^^^^^^^^^^^^^^^^^^^^^^^^^^
  File "/home/vk9342/.conda/envs/usrp/lib/python3.11/site-packages/sqlalchemy/engine/base.py", line 1986, in _exec_single_context
    self._handle_dbapi_exception(
  File "/home/vk9342/.conda/envs/usrp/lib/python3.11/site-packages/sqlalchemy/engine/base.py", line 2355, in _handle_dbapi_exception
    raise sqlalchemy_exception.with_traceback(exc_info[2]) from e
  File "/home/vk9342/.conda/envs/usrp/lib/python3.11/site-packages/sqlalchemy/engine/base.py", line 1967, in _exec_single_context
    self.dialect.do_execute(
  File "/home/vk9342/.conda/envs/usrp/lib/python3.11/site-packages/sqlalchemy/engine/default.py", line 941, in do_execute
    cursor.execute(statement, parameters)
sqlalchemy.exc.IntegrityError: (sqlite3.IntegrityError) UNIQUE constraint failed: studies.study_name
[SQL: INSERT INTO studies (study_name) VALUES (?)]
[parameters: ('Pk_nwLH_params',)]
(Background on this error at: https://sqlalche.me/e/20/gkpj)

During handling of the above exception, another exception occurred:

Traceback (most recent call last):
  File "/home/vk9342/USRP2024/pytorch/main.py", line 141, in <module>
    study = optuna.create_study(study_name=study_name, sampler=sampler, storage=storage,
            ^^^^^^^^^^^^^^^^^^^^^^^^^^^^^^^^^^^^^^^^^^^^^^^^^^^^^^^^^^^^^^^^^^^^^^^^^^^^
  File "/home/vk9342/.conda/envs/usrp/lib/python3.11/site-packages/optuna/_convert_positional_args.py", line 83, in converter_wrapper
    return func(**kwargs)
           ^^^^^^^^^^^^^^
  File "/home/vk9342/.conda/envs/usrp/lib/python3.11/site-packages/optuna/study/study.py", line 1251, in create_study
    study_id = storage.create_new_study(direction_objects, study_name)
               ^^^^^^^^^^^^^^^^^^^^^^^^^^^^^^^^^^^^^^^^^^^^^^^^^^^^^^^
  File "/home/vk9342/.conda/envs/usrp/lib/python3.11/site-packages/optuna/storages/_cached_storage.py", line 82, in create_new_study
    study_id = self._backend.create_new_study(directions=directions, study_name=study_name)
               ^^^^^^^^^^^^^^^^^^^^^^^^^^^^^^^^^^^^^^^^^^^^^^^^^^^^^^^^^^^^^^^^^^^^^^^^^^^^
  File "/home/vk9342/.conda/envs/usrp/lib/python3.11/site-packages/optuna/storages/_rdb/storage.py", line 276, in create_new_study
    raise optuna.exceptions.DuplicatedStudyError(
optuna.exceptions.DuplicatedStudyError: Another study with name 'Pk_nwLH_params' already exists. Please specify a different name, or reuse the existing one by setting `load_if_exists` (for Python API) or `--skip-if-exists` flag (for CLI).
