/var/spool/slurmd/job2309102/slurm_script: line 13: conda: command not found
[I 2024-12-12 16:34:52,367] A new study created in RDB with name: Pk_LH_params_transfer_5_debug_2
[W 2024-12-12 16:34:53,568] Trial 0 failed with parameters: {'lr': 0.023571785747269224, 'wd': 3.5236718036955836e-06, 'n_layers': 2, 'n_units_l0': 40, 'dropout_l0': 0.6041593112737735, 'dropout_final_hidden': 0.2757686728279357} because of the following error: FileNotFoundError('../real_params/latin_hypercube_params_fixed_final_5_debug_.txt not found.').
Traceback (most recent call last):
  File "/home/vk9342/.conda/envs/usrp/lib/python3.11/site-packages/optuna/study/_optimize.py", line 196, in _run_trial
    value_or_values = func(trial)
                      ^^^^^^^^^^^
  File "/home/vk9342/USRP2024/pytorch/main_fixed_final.py", line 65, in __call__
    train_loader = data.create_dataset('train', self.seed, f_Pk, f_Pk_norm,
                  ^^^^^^^^^^^^^^^^^^^^^^^^^^^^^^^^^^^^^^^^^^^^^^^^^^^^^^^^^
  File "/home/vk9342/USRP2024/pytorch/data.py", line 84, in create_dataset
    data_set = make_dataset(mode, seed, f_Pk, f_Pk_norm, f_params, cosm_type)
               ^^^^^^^^^^^^^^^^^^^^^^^^^^^^^^^^^^^^^^^^^^^^^^^^^^^^^^^^^^^^^^
  File "/home/vk9342/USRP2024/pytorch/data.py", line 32, in __init__
    params  = np.loadtxt(f_params)
              ^^^^^^^^^^^^^^^^^^^^
  File "/home/vk9342/.conda/envs/usrp/lib/python3.11/site-packages/numpy/lib/npyio.py", line 1356, in loadtxt
    arr = _read(fname, dtype=dtype, comment=comment, delimiter=delimiter,
          ^^^^^^^^^^^^^^^^^^^^^^^^^^^^^^^^^^^^^^^^^^^^^^^^^^^^^^^^^^^^^^^
  File "/home/vk9342/.conda/envs/usrp/lib/python3.11/site-packages/numpy/lib/npyio.py", line 975, in _read
    fh = np.lib._datasource.open(fname, 'rt', encoding=encoding)
         ^^^^^^^^^^^^^^^^^^^^^^^^^^^^^^^^^^^^^^^^^^^^^^^^^^^^^^^
  File "/home/vk9342/.conda/envs/usrp/lib/python3.11/site-packages/numpy/lib/_datasource.py", line 193, in open
    return ds.open(path, mode, encoding=encoding, newline=newline)
           ^^^^^^^^^^^^^^^^^^^^^^^^^^^^^^^^^^^^^^^^^^^^^^^^^^^^^^^
  File "/home/vk9342/.conda/envs/usrp/lib/python3.11/site-packages/numpy/lib/_datasource.py", line 533, in open
    raise FileNotFoundError(f"{path} not found.")
FileNotFoundError: ../real_params/latin_hypercube_params_fixed_final_5_debug_.txt not found.
[W 2024-12-12 16:34:53,570] Trial 0 failed with value None.
CUDA Available
Traceback (most recent call last):
  File "/home/vk9342/USRP2024/pytorch/main_fixed_final.py", line 186, in <module>
    study.optimize(objective, n_trials, n_jobs=n_jobs)
  File "/home/vk9342/.conda/envs/usrp/lib/python3.11/site-packages/optuna/study/study.py", line 451, in optimize
    _optimize(
  File "/home/vk9342/.conda/envs/usrp/lib/python3.11/site-packages/optuna/study/_optimize.py", line 62, in _optimize
    _optimize_sequential(
  File "/home/vk9342/.conda/envs/usrp/lib/python3.11/site-packages/optuna/study/_optimize.py", line 159, in _optimize_sequential
    frozen_trial = _run_trial(study, func, catch)
                   ^^^^^^^^^^^^^^^^^^^^^^^^^^^^^^
  File "/home/vk9342/.conda/envs/usrp/lib/python3.11/site-packages/optuna/study/_optimize.py", line 247, in _run_trial
    raise func_err
  File "/home/vk9342/.conda/envs/usrp/lib/python3.11/site-packages/optuna/study/_optimize.py", line 196, in _run_trial
    value_or_values = func(trial)
                      ^^^^^^^^^^^
  File "/home/vk9342/USRP2024/pytorch/main_fixed_final.py", line 65, in __call__
    train_loader = data.create_dataset('train', self.seed, f_Pk, f_Pk_norm, 
                   ^^^^^^^^^^^^^^^^^^^^^^^^^^^^^^^^^^^^^^^^^^^^^^^^^^^^^^^^
  File "/home/vk9342/USRP2024/pytorch/data.py", line 84, in create_dataset
    data_set = make_dataset(mode, seed, f_Pk, f_Pk_norm, f_params, cosm_type)
               ^^^^^^^^^^^^^^^^^^^^^^^^^^^^^^^^^^^^^^^^^^^^^^^^^^^^^^^^^^^^^^
  File "/home/vk9342/USRP2024/pytorch/data.py", line 32, in __init__
    params  = np.loadtxt(f_params)
              ^^^^^^^^^^^^^^^^^^^^
  File "/home/vk9342/.conda/envs/usrp/lib/python3.11/site-packages/numpy/lib/npyio.py", line 1356, in loadtxt
    arr = _read(fname, dtype=dtype, comment=comment, delimiter=delimiter,
          ^^^^^^^^^^^^^^^^^^^^^^^^^^^^^^^^^^^^^^^^^^^^^^^^^^^^^^^^^^^^^^^
  File "/home/vk9342/.conda/envs/usrp/lib/python3.11/site-packages/numpy/lib/npyio.py", line 975, in _read
    fh = np.lib._datasource.open(fname, 'rt', encoding=encoding)
         ^^^^^^^^^^^^^^^^^^^^^^^^^^^^^^^^^^^^^^^^^^^^^^^^^^^^^^^
  File "/home/vk9342/.conda/envs/usrp/lib/python3.11/site-packages/numpy/lib/_datasource.py", line 193, in open
    return ds.open(path, mode, encoding=encoding, newline=newline)
           ^^^^^^^^^^^^^^^^^^^^^^^^^^^^^^^^^^^^^^^^^^^^^^^^^^^^^^^
  File "/home/vk9342/.conda/envs/usrp/lib/python3.11/site-packages/numpy/lib/_datasource.py", line 533, in open
    raise FileNotFoundError(f"{path} not found.")
FileNotFoundError: ../real_params/latin_hypercube_params_fixed_final_5_debug_.txt not found.
