/var/spool/slurmd/job2276461/slurm_script: line 13: conda: command not found
[I 2024-11-26 13:18:38,401] A new study created in RDB with name: Pk_LH_params_dynamic_fixed_final
[W 2024-11-26 13:18:38,534] Trial 0 failed with parameters: {'lr': 1.0848444377563931e-05, 'wd': 0.4493013405644241, 'n_layers': 2, 'n_units_l0': 78, 'dropout_l2': 0.20765615623187472, 'dropout_l1': 0.6508845789797273} because of the following error: AttributeError("'tuple' object has no attribute 'to'").
Traceback (most recent call last):
  File "/home/vk9342/.conda/envs/usrp/lib/python3.11/site-packages/optuna/study/_optimize.py", line 196, in _run_trial
    value_or_values = func(trial)
                      ^^^^^^^^^^^
  File "/home/vk9342/USRP2024/pytorch/main_fixed_final.py", line 52, in __call__
    ).to(self.device)
      ^^
AttributeError: 'tuple' object has no attribute 'to'
[W 2024-11-26 13:18:38,534] Trial 0 failed with value None.
CUDA Available
Traceback (most recent call last):
  File "/home/vk9342/USRP2024/pytorch/main_fixed_final.py", line 185, in <module>
    study.optimize(objective, n_trials, n_jobs=n_jobs)
  File "/home/vk9342/.conda/envs/usrp/lib/python3.11/site-packages/optuna/study/study.py", line 451, in optimize
    _optimize(
  File "/home/vk9342/.conda/envs/usrp/lib/python3.11/site-packages/optuna/study/_optimize.py", line 62, in _optimize
    _optimize_sequential(
  File "/home/vk9342/.conda/envs/usrp/lib/python3.11/site-packages/optuna/study/_optimize.py", line 159, in _optimize_sequential
    frozen_trial = _run_trial(study, func, catch)
                   ^^^^^^^^^^^^^^^^^^^^^^^^^^^^^^
  File "/home/vk9342/.conda/envs/usrp/lib/python3.11/site-packages/optuna/study/_optimize.py", line 247, in _run_trial
    raise func_err
  File "/home/vk9342/.conda/envs/usrp/lib/python3.11/site-packages/optuna/study/_optimize.py", line 196, in _run_trial
    value_or_values = func(trial)
                      ^^^^^^^^^^^
  File "/home/vk9342/USRP2024/pytorch/main_fixed_final.py", line 52, in __call__
    ).to(self.device)
      ^^
AttributeError: 'tuple' object has no attribute 'to'
